2023-03-08 16:00:14,704 INFO    MainThread:13036 [wandb_setup.py:_flush():68] Configure stats pid to 13036
2023-03-08 16:00:14,704 INFO    MainThread:13036 [wandb_setup.py:_flush():68] Loading settings from C:\Users\canba\.config\wandb\settings
2023-03-08 16:00:14,704 INFO    MainThread:13036 [wandb_setup.py:_flush():68] Loading settings from C:\Users\canba\OneDrive\Masaüstü\OPFGNN\code\wandb\settings
2023-03-08 16:00:14,704 INFO    MainThread:13036 [wandb_setup.py:_flush():68] Loading settings from environment variables: {'_require_service': 'True'}
2023-03-08 16:00:14,704 INFO    MainThread:13036 [wandb_setup.py:_flush():68] Inferring run settings from compute environment: {'program': '<python with no main file>'}
2023-03-08 16:00:14,704 INFO    MainThread:13036 [wandb_init.py:_log_setup():492] Logging user logs to C:\Users\canba\OneDrive\Masaüstü\OPFGNN\code\wandb\run-20230308_160014-zelxbaan\logs\debug.log
2023-03-08 16:00:14,704 INFO    MainThread:13036 [wandb_init.py:_log_setup():493] Logging internal logs to C:\Users\canba\OneDrive\Masaüstü\OPFGNN\code\wandb\run-20230308_160014-zelxbaan\logs\debug-internal.log
2023-03-08 16:00:14,704 INFO    MainThread:13036 [wandb_init.py:init():532] calling init triggers
2023-03-08 16:00:14,704 INFO    MainThread:13036 [wandb_init.py:init():539] wandb.init called with sweep_config: {}
config: {'learning_rate': 0.001, 'architecture': 'Homo-GNN', 'dataset': '1-HV-mixed--0-no_sw', 'epochs': 100, 'activation': 'ReLu', 'dropout': 0.0}
2023-03-08 16:00:14,705 INFO    MainThread:13036 [wandb_init.py:init():555] re-initializing run, found existing run on stack: ml0cyuda
2023-03-08 16:00:14,706 INFO    MainThread:13036 [wandb_run.py:_finish():1854] finishing run cbml/OPF-GNN-Supervised-Homo/ml0cyuda
2023-03-08 16:00:14,706 INFO    MainThread:13036 [jupyter.py:save_history():449] not saving jupyter history
2023-03-08 16:00:14,706 INFO    MainThread:13036 [jupyter.py:save_ipynb():379] not saving jupyter notebook
2023-03-08 16:00:14,706 INFO    MainThread:13036 [wandb_init.py:_jupyter_teardown():420] cleaning up jupyter logic
2023-03-08 16:00:14,707 INFO    MainThread:13036 [wandb_run.py:_atexit_cleanup():2083] got exitcode: 0
2023-03-08 16:00:14,707 INFO    MainThread:13036 [wandb_run.py:_restore():2066] restore
2023-03-08 16:00:14,707 INFO    MainThread:13036 [wandb_run.py:_restore():2072] restore done
2023-03-08 16:01:30,865 WARNING MsgRouterThr:13036 [router.py:message_loop():77] message_loop has been closed
2023-03-08 16:01:31,400 ERROR   MainThread:13036 [wandb_init.py:init():1160] error
Traceback (most recent call last):
  File "C:\Users\canba\anaconda3\envs\code\lib\site-packages\wandb\sdk\wandb_init.py", line 1133, in init
    run = wi.init()
  File "C:\Users\canba\anaconda3\envs\code\lib\site-packages\wandb\sdk\wandb_init.py", line 567, in init
    self._wl._global_run_stack[-1].finish()
  File "C:\Users\canba\anaconda3\envs\code\lib\site-packages\wandb\sdk\wandb_run.py", line 371, in wrapper
    return func(self, *args, **kwargs)
  File "C:\Users\canba\anaconda3\envs\code\lib\site-packages\wandb\sdk\wandb_run.py", line 334, in wrapper
    return func(self, *args, **kwargs)
  File "C:\Users\canba\anaconda3\envs\code\lib\site-packages\wandb\sdk\wandb_run.py", line 1845, in finish
    return self._finish(exit_code, quiet)
  File "C:\Users\canba\anaconda3\envs\code\lib\site-packages\wandb\sdk\wandb_run.py", line 1873, in _finish
    manager._inform_finish(run_id=self._run_id)
  File "C:\Users\canba\anaconda3\envs\code\lib\site-packages\wandb\sdk\wandb_manager.py", line 187, in _inform_finish
    svc_iface._svc_inform_finish(run_id=run_id)
  File "C:\Users\canba\anaconda3\envs\code\lib\site-packages\wandb\sdk\service\service_sock.py", line 54, in _svc_inform_finish
    self._sock_client.send(inform_finish=inform_finish)
  File "C:\Users\canba\anaconda3\envs\code\lib\site-packages\wandb\sdk\lib\sock_client.py", line 211, in send
    self.send_server_request(server_req)
  File "C:\Users\canba\anaconda3\envs\code\lib\site-packages\wandb\sdk\lib\sock_client.py", line 155, in send_server_request
    self._send_message(msg)
  File "C:\Users\canba\anaconda3\envs\code\lib\site-packages\wandb\sdk\lib\sock_client.py", line 152, in _send_message
    self._sendall_with_error_handle(header + data)
  File "C:\Users\canba\anaconda3\envs\code\lib\site-packages\wandb\sdk\lib\sock_client.py", line 130, in _sendall_with_error_handle
    sent = self._sock.send(data)
ConnectionResetError: [WinError 10054] An existing connection was forcibly closed by the remote host
